<?xml version="1.0"?>
<robot name="ur5e">
  
  <!-- Base link -->
  <link name="base_link"/>
  
  <link name="base">
    <visual>
      <geometry>
        <mesh filename="meshes/ur5e/visual/base.dae"/>
      </geometry>
    </visual>
  </link>
  
  <joint name="base_link-base_fixed_joint" type="fixed">
    <origin rpy="0 0 0" xyz="0 0 0"/>
    <parent link="base_link"/>
    <child link="base"/>
  </joint>

  <!-- shoulder pan joint -->
  <joint name="shoulder_pan_joint" type="revolute">
    <origin rpy="0 0 0" xyz="0 0 0.1625"/>
    <parent link="base"/>
    <child link="shoulder_link"/>
    <axis xyz="0 0 1"/>
    <limit effort="150.0" lower="-6.2832" upper="6.2832" velocity="3.14"/>
  </joint>

  <link name="shoulder_link">
    <visual>
      <geometry>
        <mesh filename="meshes/ur5e/visual/shoulder.dae"/>
      </geometry>
    </visual>
  </link>

  <!-- shoulder lift joint -->
  <joint name="shoulder_lift_joint" type="revolute">
    <origin rpy="0 1.57079632679 0" xyz="0 0.13850 0"/>
    <parent link="shoulder_link"/>
    <child link="upper_arm_link"/>
    <axis xyz="0 1 0"/>
    <limit effort="150.0" lower="-6.2832" upper="6.2832" velocity="3.14"/>
  </joint>

  <link name="upper_arm_link">
    <visual>
      <origin rpy="0 1.57079632679 0" xyz="0 0 0.2125"/>
      <geometry>
        <mesh filename="meshes/ur5e/visual/upperarm.dae"/>
      </geometry>
    </visual>
  </link>

  <!-- elbow joint -->
  <joint name="elbow_joint" type="revolute">
    <origin rpy="0 0 0" xyz="0 -0.1197 0.425"/>
    <parent link="upper_arm_link"/>
    <child link="forearm_link"/>
    <axis xyz="0 1 0"/>
    <limit effort="150.0" lower="-3.14159265359" upper="3.14159265359" velocity="3.14"/>
  </joint>

  <link name="forearm_link">
    <visual>
      <origin rpy="0 1.57079632679 0" xyz="0 0 0.19615"/>
      <geometry>
        <mesh filename="meshes/ur5e/visual/forearm.dae"/>
      </geometry>
    </visual>
  </link>

  <!-- wrist 1 joint -->
  <joint name="wrist_1_joint" type="revolute">
    <origin rpy="0 1.57079632679 0" xyz="0 0 0.3923"/>
    <parent link="forearm_link"/>
    <child link="wrist_1_link"/>
    <axis xyz="0 0 1"/>
    <limit effort="28.0" lower="-6.2832" upper="6.2832" velocity="6.28"/>
  </joint>

  <link name="wrist_1_link">
    <visual>
      <origin rpy="0 0 0" xyz="0 0.09465 0"/>
      <geometry>
        <mesh filename="meshes/ur5e/visual/wrist1.dae"/>
      </geometry>
    </visual>
  </link>

  <!-- wrist 2 joint -->
  <joint name="wrist_2_joint" type="revolute">
    <origin rpy="0 0 0" xyz="0 0.09465 0"/>
    <parent link="wrist_1_link"/>
    <child link="wrist_2_link"/>
    <axis xyz="0 0 1"/>
    <limit effort="28.0" lower="-6.2832" upper="6.2832" velocity="6.28"/>
  </joint>

  <link name="wrist_2_link">
    <visual>
      <origin rpy="0 0 0" xyz="0 0 0.09465"/>
      <geometry>
        <mesh filename="meshes/ur5e/visual/wrist2.dae"/>
      </geometry>
    </visual>
  </link>

  <!-- wrist 3 joint -->
  <joint name="wrist_3_joint" type="revolute">
    <origin rpy="0 0 0" xyz="0 0 0.09465"/>
    <parent link="wrist_2_link"/>
    <child link="wrist_3_link"/>
    <axis xyz="0 0 1"/>
    <limit effort="28.0" lower="-6.2832" upper="6.2832" velocity="6.28"/>
  </joint>

  <link name="wrist_3_link">
    <visual>
      <origin rpy="0 1.57079632679 0" xyz="0 0.0823 0"/>
      <geometry>
        <mesh filename="meshes/ur5e/visual/wrist3.dae"/>
      </geometry>
    </visual>
  </link>

  <!-- Tool link -->
  <link name="tool0"/>

  <joint name="wrist_3-tool0" type="fixed">
    <parent link="wrist_3_link"/>
    <child link="tool0"/>
    <origin rpy="-1.57079632679 0 0" xyz="0 0.0823 0"/>
  </joint>

</robot>
